2020-08-13 10:36:48,275 [INFO ]  Starting Rasa server on http://localhost:5005
2020-08-13 10:36:50,172 [ERROR]  Could not load model due to File '/tmp/tmp2z99g72p/nlu/component_5_DIETClassifier.index_tag_id_mapping.pkl' does not exist..
2020-08-13 10:36:50,173 [ERROR]  Experienced exception while trying to serve
Traceback (most recent call last):
  File "/opt/venv/lib/python3.6/site-packages/rasa/utils/io.py", line 137, in read_file
    with open(filename, encoding=encoding) as f:
FileNotFoundError: [Errno 2] No such file or directory: '/tmp/tmp2z99g72p/nlu/component_5_DIETClassifier.index_tag_id_mapping.pkl'

During handling of the above exception, another exception occurred:

Traceback (most recent call last):
  File "/opt/venv/lib/python3.6/site-packages/sanic/app.py", line 1167, in run
    serve(**server_settings)
  File "/opt/venv/lib/python3.6/site-packages/sanic/server.py", line 892, in serve
    trigger_events(before_start, loop)
  File "/opt/venv/lib/python3.6/site-packages/sanic/server.py", line 668, in trigger_events
    loop.run_until_complete(result)
  File "uvloop/loop.pyx", line 1456, in uvloop.loop.Loop.run_until_complete
  File "/opt/venv/lib/python3.6/site-packages/rasa/core/run.py", line 258, in load_agent_on_start
    action_endpoint=endpoints.action,
  File "/opt/venv/lib/python3.6/site-packages/rasa/core/agent.py", line 271, in load_agent
    remote_storage=remote_storage,
  File "/opt/venv/lib/python3.6/site-packages/rasa/core/agent.py", line 938, in load_local_model
    path_to_model_archive=model_archive,
  File "/opt/venv/lib/python3.6/site-packages/rasa/core/agent.py", line 387, in load
    interpreter = NaturalLanguageInterpreter.create(nlu_model)
  File "/opt/venv/lib/python3.6/site-packages/rasa/core/interpreter.py", line 54, in create
    return RasaNLUInterpreter(model_directory=obj)
  File "/opt/venv/lib/python3.6/site-packages/rasa/core/interpreter.py", line 274, in __init__
    self._load_interpreter()
  File "/opt/venv/lib/python3.6/site-packages/rasa/core/interpreter.py", line 297, in _load_interpreter
    self.interpreter = Interpreter.load(self.model_directory)
  File "/opt/venv/lib/python3.6/site-packages/rasa/nlu/model.py", line 301, in load
    return Interpreter.create(model_metadata, component_builder, skip_validation)
  File "/opt/venv/lib/python3.6/site-packages/rasa/nlu/model.py", line 328, in create
    component_meta, model_metadata.model_dir, model_metadata, **context
  File "/opt/venv/lib/python3.6/site-packages/rasa/nlu/components.py", line 718, in load_component
    component_meta, model_dir, model_metadata, cached_component, **context
  File "/opt/venv/lib/python3.6/site-packages/rasa/nlu/registry.py", line 231, in load_component_by_meta
    component_meta, model_dir, metadata, cached_component, **kwargs
  File "/opt/venv/lib/python3.6/site-packages/rasa/nlu/classifiers/diet_classifier.py", line 852, in load
    ) = cls._load_from_files(meta, model_dir)
  File "/opt/venv/lib/python3.6/site-packages/rasa/nlu/classifiers/diet_classifier.py", line 879, in _load_from_files
    model_dir / f"{file_name}.index_tag_id_mapping.pkl"
  File "/opt/venv/lib/python3.6/site-packages/rasa/utils/io.py", line 442, in json_unpickle
    file_content = read_file(file_name)
  File "/opt/venv/lib/python3.6/site-packages/rasa/utils/io.py", line 140, in read_file
    raise ValueError(f"File '{filename}' does not exist.")
ValueError: File '/tmp/tmp2z99g72p/nlu/component_5_DIETClassifier.index_tag_id_mapping.pkl' does not exist.
2020-08-13 10:41:49,811 [INFO ]  Starting Rasa server on http://localhost:5005
2020-08-13 10:41:50,977 [ERROR]  Could not load model due to File '/tmp/tmp_vlred8o/nlu/component_5_DIETClassifier.index_tag_id_mapping.pkl' does not exist..
2020-08-13 10:41:50,979 [ERROR]  Experienced exception while trying to serve
Traceback (most recent call last):
  File "/opt/venv/lib/python3.6/site-packages/rasa/utils/io.py", line 137, in read_file
    with open(filename, encoding=encoding) as f:
FileNotFoundError: [Errno 2] No such file or directory: '/tmp/tmp_vlred8o/nlu/component_5_DIETClassifier.index_tag_id_mapping.pkl'

During handling of the above exception, another exception occurred:

Traceback (most recent call last):
  File "/opt/venv/lib/python3.6/site-packages/sanic/app.py", line 1167, in run
    serve(**server_settings)
  File "/opt/venv/lib/python3.6/site-packages/sanic/server.py", line 892, in serve
    trigger_events(before_start, loop)
  File "/opt/venv/lib/python3.6/site-packages/sanic/server.py", line 668, in trigger_events
    loop.run_until_complete(result)
  File "uvloop/loop.pyx", line 1456, in uvloop.loop.Loop.run_until_complete
  File "/opt/venv/lib/python3.6/site-packages/rasa/core/run.py", line 258, in load_agent_on_start
    action_endpoint=endpoints.action,
  File "/opt/venv/lib/python3.6/site-packages/rasa/core/agent.py", line 271, in load_agent
    remote_storage=remote_storage,
  File "/opt/venv/lib/python3.6/site-packages/rasa/core/agent.py", line 938, in load_local_model
    path_to_model_archive=model_archive,
  File "/opt/venv/lib/python3.6/site-packages/rasa/core/agent.py", line 387, in load
    interpreter = NaturalLanguageInterpreter.create(nlu_model)
  File "/opt/venv/lib/python3.6/site-packages/rasa/core/interpreter.py", line 54, in create
    return RasaNLUInterpreter(model_directory=obj)
  File "/opt/venv/lib/python3.6/site-packages/rasa/core/interpreter.py", line 274, in __init__
    self._load_interpreter()
  File "/opt/venv/lib/python3.6/site-packages/rasa/core/interpreter.py", line 297, in _load_interpreter
    self.interpreter = Interpreter.load(self.model_directory)
  File "/opt/venv/lib/python3.6/site-packages/rasa/nlu/model.py", line 301, in load
    return Interpreter.create(model_metadata, component_builder, skip_validation)
  File "/opt/venv/lib/python3.6/site-packages/rasa/nlu/model.py", line 328, in create
    component_meta, model_metadata.model_dir, model_metadata, **context
  File "/opt/venv/lib/python3.6/site-packages/rasa/nlu/components.py", line 718, in load_component
    component_meta, model_dir, model_metadata, cached_component, **context
  File "/opt/venv/lib/python3.6/site-packages/rasa/nlu/registry.py", line 231, in load_component_by_meta
    component_meta, model_dir, metadata, cached_component, **kwargs
  File "/opt/venv/lib/python3.6/site-packages/rasa/nlu/classifiers/diet_classifier.py", line 852, in load
    ) = cls._load_from_files(meta, model_dir)
  File "/opt/venv/lib/python3.6/site-packages/rasa/nlu/classifiers/diet_classifier.py", line 879, in _load_from_files
    model_dir / f"{file_name}.index_tag_id_mapping.pkl"
  File "/opt/venv/lib/python3.6/site-packages/rasa/utils/io.py", line 442, in json_unpickle
    file_content = read_file(file_name)
  File "/opt/venv/lib/python3.6/site-packages/rasa/utils/io.py", line 140, in read_file
    raise ValueError(f"File '{filename}' does not exist.")
ValueError: File '/tmp/tmp_vlred8o/nlu/component_5_DIETClassifier.index_tag_id_mapping.pkl' does not exist.
2020-08-13 10:43:44,130 [INFO ]  Starting Rasa server on http://localhost:5005
2020-08-13 10:43:45,242 [ERROR]  Could not load model due to File '/tmp/tmponj1cx7l/nlu/component_5_DIETClassifier.index_tag_id_mapping.pkl' does not exist..
2020-08-13 10:43:45,242 [ERROR]  Experienced exception while trying to serve
Traceback (most recent call last):
  File "/opt/venv/lib/python3.6/site-packages/rasa/utils/io.py", line 137, in read_file
    with open(filename, encoding=encoding) as f:
FileNotFoundError: [Errno 2] No such file or directory: '/tmp/tmponj1cx7l/nlu/component_5_DIETClassifier.index_tag_id_mapping.pkl'

During handling of the above exception, another exception occurred:

Traceback (most recent call last):
  File "/opt/venv/lib/python3.6/site-packages/sanic/app.py", line 1167, in run
    serve(**server_settings)
  File "/opt/venv/lib/python3.6/site-packages/sanic/server.py", line 892, in serve
    trigger_events(before_start, loop)
  File "/opt/venv/lib/python3.6/site-packages/sanic/server.py", line 668, in trigger_events
    loop.run_until_complete(result)
  File "uvloop/loop.pyx", line 1456, in uvloop.loop.Loop.run_until_complete
  File "/opt/venv/lib/python3.6/site-packages/rasa/core/run.py", line 258, in load_agent_on_start
    action_endpoint=endpoints.action,
  File "/opt/venv/lib/python3.6/site-packages/rasa/core/agent.py", line 271, in load_agent
    remote_storage=remote_storage,
  File "/opt/venv/lib/python3.6/site-packages/rasa/core/agent.py", line 938, in load_local_model
    path_to_model_archive=model_archive,
  File "/opt/venv/lib/python3.6/site-packages/rasa/core/agent.py", line 387, in load
    interpreter = NaturalLanguageInterpreter.create(nlu_model)
  File "/opt/venv/lib/python3.6/site-packages/rasa/core/interpreter.py", line 54, in create
    return RasaNLUInterpreter(model_directory=obj)
  File "/opt/venv/lib/python3.6/site-packages/rasa/core/interpreter.py", line 274, in __init__
    self._load_interpreter()
  File "/opt/venv/lib/python3.6/site-packages/rasa/core/interpreter.py", line 297, in _load_interpreter
    self.interpreter = Interpreter.load(self.model_directory)
  File "/opt/venv/lib/python3.6/site-packages/rasa/nlu/model.py", line 301, in load
    return Interpreter.create(model_metadata, component_builder, skip_validation)
  File "/opt/venv/lib/python3.6/site-packages/rasa/nlu/model.py", line 328, in create
    component_meta, model_metadata.model_dir, model_metadata, **context
  File "/opt/venv/lib/python3.6/site-packages/rasa/nlu/components.py", line 718, in load_component
    component_meta, model_dir, model_metadata, cached_component, **context
  File "/opt/venv/lib/python3.6/site-packages/rasa/nlu/registry.py", line 231, in load_component_by_meta
    component_meta, model_dir, metadata, cached_component, **kwargs
  File "/opt/venv/lib/python3.6/site-packages/rasa/nlu/classifiers/diet_classifier.py", line 852, in load
    ) = cls._load_from_files(meta, model_dir)
  File "/opt/venv/lib/python3.6/site-packages/rasa/nlu/classifiers/diet_classifier.py", line 879, in _load_from_files
    model_dir / f"{file_name}.index_tag_id_mapping.pkl"
  File "/opt/venv/lib/python3.6/site-packages/rasa/utils/io.py", line 442, in json_unpickle
    file_content = read_file(file_name)
  File "/opt/venv/lib/python3.6/site-packages/rasa/utils/io.py", line 140, in read_file
    raise ValueError(f"File '{filename}' does not exist.")
ValueError: File '/tmp/tmponj1cx7l/nlu/component_5_DIETClassifier.index_tag_id_mapping.pkl' does not exist.
2020-08-13 10:47:19,682 [INFO ]  Starting Rasa server on http://localhost:5005
2020-08-13 10:47:20,746 [ERROR]  Could not load model due to File '/tmp/tmpbwps0lqy/nlu/component_5_DIETClassifier.index_tag_id_mapping.pkl' does not exist..
2020-08-13 10:47:20,747 [ERROR]  Experienced exception while trying to serve
Traceback (most recent call last):
  File "/opt/venv/lib/python3.6/site-packages/rasa/utils/io.py", line 137, in read_file
    with open(filename, encoding=encoding) as f:
FileNotFoundError: [Errno 2] No such file or directory: '/tmp/tmpbwps0lqy/nlu/component_5_DIETClassifier.index_tag_id_mapping.pkl'

During handling of the above exception, another exception occurred:

Traceback (most recent call last):
  File "/opt/venv/lib/python3.6/site-packages/sanic/app.py", line 1167, in run
    serve(**server_settings)
  File "/opt/venv/lib/python3.6/site-packages/sanic/server.py", line 892, in serve
    trigger_events(before_start, loop)
  File "/opt/venv/lib/python3.6/site-packages/sanic/server.py", line 668, in trigger_events
    loop.run_until_complete(result)
  File "uvloop/loop.pyx", line 1456, in uvloop.loop.Loop.run_until_complete
  File "/opt/venv/lib/python3.6/site-packages/rasa/core/run.py", line 258, in load_agent_on_start
    action_endpoint=endpoints.action,
  File "/opt/venv/lib/python3.6/site-packages/rasa/core/agent.py", line 271, in load_agent
    remote_storage=remote_storage,
  File "/opt/venv/lib/python3.6/site-packages/rasa/core/agent.py", line 938, in load_local_model
    path_to_model_archive=model_archive,
  File "/opt/venv/lib/python3.6/site-packages/rasa/core/agent.py", line 387, in load
    interpreter = NaturalLanguageInterpreter.create(nlu_model)
  File "/opt/venv/lib/python3.6/site-packages/rasa/core/interpreter.py", line 54, in create
    return RasaNLUInterpreter(model_directory=obj)
  File "/opt/venv/lib/python3.6/site-packages/rasa/core/interpreter.py", line 274, in __init__
    self._load_interpreter()
  File "/opt/venv/lib/python3.6/site-packages/rasa/core/interpreter.py", line 297, in _load_interpreter
    self.interpreter = Interpreter.load(self.model_directory)
  File "/opt/venv/lib/python3.6/site-packages/rasa/nlu/model.py", line 301, in load
    return Interpreter.create(model_metadata, component_builder, skip_validation)
  File "/opt/venv/lib/python3.6/site-packages/rasa/nlu/model.py", line 328, in create
    component_meta, model_metadata.model_dir, model_metadata, **context
  File "/opt/venv/lib/python3.6/site-packages/rasa/nlu/components.py", line 718, in load_component
    component_meta, model_dir, model_metadata, cached_component, **context
  File "/opt/venv/lib/python3.6/site-packages/rasa/nlu/registry.py", line 231, in load_component_by_meta
    component_meta, model_dir, metadata, cached_component, **kwargs
  File "/opt/venv/lib/python3.6/site-packages/rasa/nlu/classifiers/diet_classifier.py", line 852, in load
    ) = cls._load_from_files(meta, model_dir)
  File "/opt/venv/lib/python3.6/site-packages/rasa/nlu/classifiers/diet_classifier.py", line 879, in _load_from_files
    model_dir / f"{file_name}.index_tag_id_mapping.pkl"
  File "/opt/venv/lib/python3.6/site-packages/rasa/utils/io.py", line 442, in json_unpickle
    file_content = read_file(file_name)
  File "/opt/venv/lib/python3.6/site-packages/rasa/utils/io.py", line 140, in read_file
    raise ValueError(f"File '{filename}' does not exist.")
ValueError: File '/tmp/tmpbwps0lqy/nlu/component_5_DIETClassifier.index_tag_id_mapping.pkl' does not exist.
2020-08-14 04:02:52,802 [INFO ]  Starting Rasa server on http://localhost:5005
2020-08-14 04:03:04,176 [INFO ]  Rasa server is up and running.
2020-08-14 04:06:34,337 [ERROR]  Task exception was never retrieved
future: <Task finished coro=<AsyncServer._handle_event_internal() done, defined at /opt/venv/lib/python3.7/site-packages/socketio/asyncio_server.py:469> exception=KeyError('message')>
Traceback (most recent call last):
  File "/opt/venv/lib/python3.7/site-packages/socketio/asyncio_server.py", line 470, in _handle_event_internal
    r = await server._trigger_event(data[0], namespace, sid, *data[1:])
  File "/opt/venv/lib/python3.7/site-packages/socketio/asyncio_server.py", line 498, in _trigger_event
    ret = await self.handlers[namespace][event](*args)
  File "/opt/venv/lib/python3.7/site-packages/rasa/core/channels/socketio.py", line 215, in handle_message
    data["message"], output_channel, sender_id, input_channel=self.name()
KeyError: 'message'
2020-08-14 05:19:10,515 [ERROR]  Task exception was never retrieved
future: <Task finished coro=<AsyncServer._handle_event_internal() done, defined at /opt/venv/lib/python3.7/site-packages/socketio/asyncio_server.py:469> exception=KeyError('message')>
Traceback (most recent call last):
  File "/opt/venv/lib/python3.7/site-packages/socketio/asyncio_server.py", line 470, in _handle_event_internal
    r = await server._trigger_event(data[0], namespace, sid, *data[1:])
  File "/opt/venv/lib/python3.7/site-packages/socketio/asyncio_server.py", line 498, in _trigger_event
    ret = await self.handlers[namespace][event](*args)
  File "/opt/venv/lib/python3.7/site-packages/rasa/core/channels/socketio.py", line 215, in handle_message
    data["message"], output_channel, sender_id, input_channel=self.name()
KeyError: 'message'
2020-08-14 05:29:02,706 [ERROR]  Task was destroyed but it is pending!
task: <Task pending coro=<AsyncServer._service_task() running at /opt/venv/lib/python3.7/site-packages/engineio/asyncio_server.py:451> wait_for=<Future pending cb=[<TaskWakeupMethWrapper object at 0x7fc11ed5ec50>()]>>
2020-08-17 04:11:09,258 [INFO ]  Starting Rasa server on http://localhost:5005
2020-08-17 04:11:18,457 [INFO ]  Rasa server is up and running.
2020-08-17 04:11:23,108 [ERROR]  Task exception was never retrieved
future: <Task finished coro=<AsyncServer._handle_event_internal() done, defined at /opt/venv/lib/python3.7/site-packages/socketio/asyncio_server.py:469> exception=KeyError('message')>
Traceback (most recent call last):
  File "/opt/venv/lib/python3.7/site-packages/socketio/asyncio_server.py", line 470, in _handle_event_internal
    r = await server._trigger_event(data[0], namespace, sid, *data[1:])
  File "/opt/venv/lib/python3.7/site-packages/socketio/asyncio_server.py", line 498, in _trigger_event
    ret = await self.handlers[namespace][event](*args)
  File "/opt/venv/lib/python3.7/site-packages/rasa/core/channels/socketio.py", line 215, in handle_message
    data["message"], output_channel, sender_id, input_channel=self.name()
KeyError: 'message'
2020-08-17 05:13:41,852 [INFO ]  Starting Rasa server on http://localhost:5005
2020-08-17 05:13:51,358 [INFO ]  Rasa server is up and running.
